Workbook

Sheet Instructions
A1: LAB 1B: DATA CLEANING IN EXCEL
A2: Level 6 - Data Technology & Innovation (DTI)
A4: LEARNING OUTCOMES: ✓ Load and inspect financial datasets ✓ Identify data quality issues using Excel tools ✓ Apply cleaning techniques (filters, formulas, conditional formatting) ✓ Document decisions for audit trail PORTFOLIO OUTCOME: Completed Excel workbook demonstrating data cleaning
A13: HOW TO USE THIS LAB: 1. Start with the 'Raw_Data' sheet (don't edit it!) 2. Copy data to 'Work_Here' sheet 3. Follow the steps below 4. Check your work against the 'Clean_Data' sheet 5. Download this completed file for your portfolio
A20: STEP 1: INITIAL INSPECTION (10 mins) ------------------------------------ Go to 'Raw_Data' sheet Tasks: □ How many rows? (Use Ctrl+Down from A1) □ Apply AutoFilter (Data > Filter) □ Look at each column - notice anything unusual? | K20: STEP 4: OUTLIER DETECTION A) VISUALIZE TRANSACTION AMOUNTS □ Select 'amount' column □ Insert > Charts > Box and Whisker (or Histogram) □ Look for extreme values B) CALCULATE IQR METHOD Create a small calculation table in cells K2:L10: | Metric | Formula | Value | |---------------|--------------------------------------|--------| | Q1 | =QUARTILE.INC(C:C,1) | [auto] | | Q3 | =QUARTILE.INC(C:C,3) | [auto] | | IQR | =L3-L2 | [auto] | | Lower Bound | =L2-1.5*L4 | [auto] | | Upper Bound | =L3+1.5*L4 | [auto] | C) FLAG OUTLIERS (DON'T DELETE!) □ Add new column header: "outlier_flag" □ In first data row, enter formula: =IF(OR([@amount]<$L$5, [@amount]>$L$6), 1, 0) □ Copy formula down entire column 💡 FINANCE BEST PRACTICE: High-value transactions could be legitimate! We FLAG them for investigation, not automatic deletion. D) FILTER TO SEE OUTLIERS □ Filter 'outlier_flag' → Show only 1 □ Sort by 'amount' (highest to lowest) □ Review top 10 transactions Question: Do these look legitimate or suspicious?
A28: STEP 2: COPY & SETUP ------------------------------ □ Copy ALL data from 'Raw_Data' (Ctrl+A, Ctrl+C) □ Paste into 'Work_Here' sheet (Ctrl+V) □ Apply AutoFilter to your working copy □ Freeze top row (View > Freeze Panes > Freeze Top Row)
A37: STEP 3: MISSING VALUE ANALYSIS A) IDENTIFY MISSING VALUES □ Click on 'amount' column filter → Look for (Blanks) - how many? □ Repeat for 'date', 'category', 'merchant_name', 'region' □ Use conditional formatting to highlight blanks: - Select all data (Ctrl+A) - Home > Conditional Formatting > Highlight Cell Rules > Blanks - Choose red fill 💡 WHAT YOU SHOULD SEE: • ~500 missing amounts (5%) • ~300 missing dates (3%) • ~800 missing categories (8%) • ~1000 missing merchants (10%) B) HANDLE MISSING VALUES Strategy: 1. Missing 'amount' → DELETE ROWS Why? Can't analyze financial data without transaction values! Steps: □ Filter 'amount' column → Show only (Blanks) □ Select all visible rows (click row numbers) □ Right-click > Delete Row □ Clear filter 2. Missing 'date' → DELETE ROWS Why? Need dates for time-series analysis Steps: □ Filter 'date' column → Show only (Blanks) □ Select all visible rows → Delete Row □ Clear filter 3. Missing 'category' → FILL with "Uncategorised" Steps: □ Filter 'category' → Show only (Blanks) □ Select all blank cells in 'category' column □ Type: Uncategorised □ Press Ctrl+Enter (fills all selected cells) □ Clear filter 4. Missing 'merchant_name' → FILL with "Unknown Merchant" Steps: (same as above) 5. Missing 'region' → FILL with most common region Steps: □ First, find most common region: - In empty cell: =MODE.SNGL() - actually use: - Count each region manually or use pivot table □ Fill blanks with that region
K55: STEP 5: DATA STANDARDISATION A) FIX CATEGORY CAPITALISATION □ Select 'category' column □ Add helper column (next to category) □ Formula: =PROPER(E2) □ Copy down, then Copy > Paste Values □ Delete original, rename helper column B) FIX REGION TYPOS Look for: "Nrth", "Sth", "Est", "Wst" □ Use Find & Replace (Ctrl+H): - Find: Nrth → Replace with: North - Find: Sth → Replace with: South - Find: Est → Replace with: East - Find: Wst → Replace with: West □ Also fix lowercase: north → North, etc. C) VERIFY STANDARDISATION □ Filter 'category' - should only see proper case □ Filter 'region' - should only see: North, South, East, West
K76: STEP 6: YOUR TURN - CHALLENGE --------------------------------- TASK: Standardize 'payment_method' column 1. Check for inconsistencies (card vs Card vs CARD) 2. Standardize to proper case 3. Count transactions per payment method 4. Create a simple bar chart Try it yourself! Use the techniques from Step 5.

Sheet Raw_Data
A1: transaction_id | B1: date | C1: customer_id | D1: amount | E1: category | F1: region | G1: payment_method | H1: merchant_name
A2: TXN_001114 | B2: 45352 | C2: CUST_3711 | D2: 863.13 | E2: Training | F2: West | G2: Cash | H2: Marketing Agency Ltd
A3: TXN_006267 | B3: 45444 | C3: CUST_6073 | D3: 1783.51 | E3: Marketing | F3: South | G3: Transfer | H3: Advisory Partners
A4: TXN_005820 | B4: 45566 | C4: CUST_2381 | D4: 1200.51 | E4: Travel | F4: North | G4: Transfer | H4: Tech Solutions Ltd
A5: TXN_004797 | B5: 45384 | C5: CUST_4899 | D5: 1981.6 | E5: Travel | F5: South | G5: Cash | H5: Cloud Services Inc
A6: TXN_004823 | B6: 45414 | C6: CUST_2342 | D6: 943.9 | E6: Marketing | F6: South | G6: Direct Debit | H6: Conference Center
A7: TXN_009190 | B7: 45354 | C7: CUST_1255 | D7: 1147.27 | F7: North | G7: Cash | H7: Stationary World
A8: TXN_009475 | B8: 45476 | C8: CUST_7457 | D8: 1772.48 | E8: Maintenance | F8: North | G8: Card | H8: Legal Advisors
A9: TXN_001489 | B9: 45507 | C9: CUST_1894 | D9: 108.64 | E9: Equipment | F9: North | G9: Direct Debit | H9: Software Vendor
A10: TXN_000008 | B10: 45538 | C10: CUST_5426 | D10: 277.27 | E10: it services | F10: West | G10: Direct Debit | H10: Maintenance Services
A11: TXN_003162 | B11: 45599 | C11: CUST_7614 | D11: 5217.33 | E11: IT Services | F11: East | G11: Cash | H11: Cloud Services Inc
A12: TXN_003740 | B12: 45447 | C12: CUST_1919 | D12: 1155.72 | E12: Utilities | F12: North | G12: Transfer | H12: Marketing Agency Ltd
A13: TXN_006854 | B13: 45297 | C13: CUST_3105 | D13: 1903.42 | E13: Legal | F13: South | G13: Direct Debit | H13: Tech Solutions Ltd
A14: TXN_009200 | B14: 45328 | C14: CUST_6592 | D14: 1886.04 | E14: Office Supplies | F14: East | G14: Transfer | H14: Cloud Services Inc
A15: TXN_005241 | B15: 45449 | C15: CUST_3657 | D15: 758.62 | E15: Office Supplies | F15: East | G15: Cash | H15: Maintenance Services
A16: TXN_006394 | B16: 45633 | C16: CUST_7719 | D16: 926.7 | E16: IT Services | F16: West | G16: Direct Debit | H16: Industrial Supply Co
A17: TXN_004328 | B17: 45359 | C17: CUST_9975 | D17: 603.54 | E17: Travel | F17: North | G17: Card
A18: TXN_005057 | B18: 45604 | C18: CUST_7691 | D18: 159.55 | E18: Marketing | F18: East | G18: Cash | H18: Advisory Partners
A19: TXN_002009 | B19: 45360 | C19: CUST_2246 | D19: 1225.14 | E19: IT Services | F19: East | G19: Cash | H19: Tech Solutions Ltd
A20: TXN_008775 | B20: 45360 | C20: CUST_2912 | D20: 1899.33 | E20: equipment | F20: North | G20: Direct Debit
A21: TXN_009006 | B21: 45452 | C21: CUST_1234 | E21: Marketing | F21: South | G21: Transfer | H21: Power Supply Co
A22: TXN_004566 | B22: 45635 | C22: CUST_5042 | D22: 931.16 | E22: Utilities | F22: North | G22: Card | H22: Cloud Services Inc
A23: TXN_005371 | B23: 45635 | C23: CUST_4201 | D23: 110.46 | F23: East | G23: Card | H23: Maintenance Services
A24: TXN_003483 | B24: 45361 | C24: CUST_1644 | D24: 412.95 | E24: Utilities | F24: South | G24: Cash | H24: Learning Academy
A25: TXN_004348 | B25: 45422 | C25: CUST_2902 | D25: 1161.23 | E25: Training | F25: East | G25: Cash
A26: TXN_001881 | B26: 45545 | C26: CUST_8967 | D26: 1900.35 | E26: IT Services | F26: North | G26: Card | H26: Tech Solutions Ltd
A27: TXN_006677 | B27: 45545 | C27: CUST_6972 | D27: 936.79 | E27: Equipment | F27: North | G27: Direct Debit | H27: Learning Academy
A28: TXN_007073 | B28: 45606 | C28: CUST_1393 | D28: 299.37 | E28: Office Supplies | F28: East | G28: Direct Debit | H28: Stationary World
A29: TXN_000437 | B29: 45636 | C29: CUST_1412 | D29: 1019.84 | E29: Maintenance | F29: West | G29: Cash | H29: Learning Academy
A30: TXN_008588 | B30: 45576 | C30: CUST_2883 | D30: 1768.53 | E30: Training | F30: East | G30: Card | H30: Industrial Supply Co
A31: TXN_006791 | B31: 45607 | C31: CUST_7571 | D31: 1601.95 | E31: Travel | F31: North | G31: Cash | H31: City Hotel
A32: TXN_006720 | B32: 45394 | C32: CUST_9328 | E32: Travel | F32: East | G32: Direct Debit | H32: Advisory Partners
A33: TXN_009741 | B33: 45455 | C33: CUST_6606 | D33: 662.11 | E33: Training | F33: South | G33: Cash | H33: Tech Solutions Ltd
A34: TXN_008610 | B34: 45547 | C34: CUST_4883 | D34: 1460.32 | E34: Legal | F34: North | G34: Card | H34: Software Vendor
A35: TXN_007634 | B35: 45577 | C35: CUST_6122 | D35: 409.96 | E35: Utilities | F35: East | G35: Direct Debit | H35: Legal Advisors
A36: TXN_004140 | B36: 45304 | C36: CUST_2716 | D36: 1199.89 | E36: Training | F36: South | G36: Transfer | H36: Conference Center
A37: TXN_008001 | B37: 45364 | C37: CUST_8616 | D37: 1250.99 | E37: Consulting | F37: North | G37: Cash | H37: British Airways
A38: TXN_004532 | B38: 45305 | C38: CUST_7638 | D38: 1352.88 | E38: Legal | F38: North | G38: Cash | H38: Conference Center
A39: TXN_003647 | B39: 45365 | C39: CUST_9235 | D39: 1644.34 | E39: Training | F39: North | G39: Cash | H39: Learning Academy
A40: TXN_009462 | B40: 45396 | C40: CUST_6614 | D40: 784.87 | E40: Marketing | F40: South | G40: Transfer | H40: British Airways
...

Sheet Work_Here
A1: Copy data from Raw_Data sheet to start. Follow Instructions sheet.
A2: transaction_id | B2: date | C2: customer_id | D2: amount | E2: category | F2: region | G2: payment_method | H2: merchant_name | K2: Formula
K3: Metric | L3: Formula
K4: Q1 | L4: =_xlfn.QUARTILE.INC(D:D,1) -> #NUM!
K5: Q3 | L5: =_xlfn.QUARTILE.INC(D:D,3) -> #NUM!
K6: IQR | L6: =L5-L4 -> #NUM!
K7: Lower Bound | L7: =L4-1.5*L6 -> #NUM!
K8: Upper Bound | L8: =L5+1.5*L6 -> #NUM!

Sheet Clean_Data
A1: transaction_id | B1: date | C1: customer_id | D1: amount | E1: Category | F1: region | G1: payment_method | H1: merchant_name | I1: outlier_flag
A2: TXN_001114 | B2: 45352 | C2: CUST_3711 | D2: 863.13 | E2: Training | F2: West | G2: Cash | H2: Marketing Agency Ltd | I2: =IF(OR(financial_transactions35[[#This Row],[amount]]<$L$16, financial_transactions35[[#This Row],[amount]]>$L$17), 1, 0) -> 1 | K2: Metric | L2: Formula
A3: TXN_006267 | B3: 45444 | C3: CUST_6073 | D3: 1783.51 | E3: Marketing | F3: South | G3: Transfer | H3: Advisory Partners | I3: =IF(OR(financial_transactions35[[#This Row],[amount]]<$L$16, financial_transactions35[[#This Row],[amount]]>$L$17), 1, 0) -> 1 | K3: Q1 | L3: =_xlfn.QUARTILE.INC(D:D,1) -> 570.95
A4: TXN_005820 | B4: 45566 | C4: CUST_2381 | D4: 1200.51 | E4: Travel | F4: North | G4: Transfer | H4: Tech Solutions Ltd | I4: =IF(OR(financial_transactions35[[#This Row],[amount]]<$L$16, financial_transactions35[[#This Row],[amount]]>$L$17), 1, 0) -> 1 | K4: Q3 | L4: =_xlfn.QUARTILE.INC(D:D,3) -> 1598.07
A5: TXN_004797 | B5: 45384 | C5: CUST_4899 | D5: 1981.6 | E5: Travel | F5: South | G5: Cash | H5: Cloud Services Inc | I5: =IF(OR(financial_transactions35[[#This Row],[amount]]<$L$16, financial_transactions35[[#This Row],[amount]]>$L$17), 1, 0) -> 1 | K5: IQR | L5: =L4-L3 -> 1027.12
A6: TXN_004823 | B6: 45414 | C6: CUST_2342 | D6: 943.9 | E6: Marketing | F6: South | G6: Direct Debit | H6: Conference Center | I6: =IF(OR(financial_transactions35[[#This Row],[amount]]<$L$16, financial_transactions35[[#This Row],[amount]]>$L$17), 1, 0) -> 1 | K6: Lower Bound | L6: =L3-1.5*L5 -> -969.73
A7: TXN_009190 | B7: 45354 | C7: CUST_1255 | D7: 1147.27 | E7: Uncategorised | F7: North | G7: Cash | H7: Stationary World | I7: =IF(OR(financial_transactions35[[#This Row],[amount]]<$L$16, financial_transactions35[[#This Row],[amount]]>$L$17), 1, 0) -> 1 | K7: Upper Bound | L7: =L4+1.5*L5 -> 3138.75
A8: TXN_009475 | B8: 45476 | C8: CUST_7457 | D8: 1772.48 | E8: Maintenance | F8: North | G8: Card | H8: Legal Advisors | I8: =IF(OR(financial_transactions35[[#This Row],[amount]]<$L$16, financial_transactions35[[#This Row],[amount]]>$L$17), 1, 0) -> 1
A9: TXN_001489 | B9: 45507 | C9: CUST_1894 | D9: 108.64 | E9: Equipment | F9: North | G9: Direct Debit | H9: Software Vendor | I9: =IF(OR(financial_transactions35[[#This Row],[amount]]<$L$16, financial_transactions35[[#This Row],[amount]]>$L$17), 1, 0) -> 1
A10: TXN_000008 | B10: 45538 | C10: CUST_5426 | D10: 277.27 | E10: It Services | F10: West | G10: Direct Debit | H10: Maintenance Services | I10: =IF(OR(financial_transactions35[[#This Row],[amount]]<$L$16, financial_transactions35[[#This Row],[amount]]>$L$17), 1, 0) -> 1
A11: TXN_003162 | B11: 45599 | C11: CUST_7614 | D11: 5217.33 | E11: It Services | F11: East | G11: Cash | H11: Cloud Services Inc | I11: =IF(OR(financial_transactions35[[#This Row],[amount]]<$L$16, financial_transactions35[[#This Row],[amount]]>$L$17), 1, 0) -> 1
A12: TXN_003740 | B12: 45447 | C12: CUST_1919 | D12: 1155.72 | E12: Utilities | F12: North | G12: Transfer | H12: Marketing Agency Ltd | I12: =IF(OR(financial_transactions35[[#This Row],[amount]]<$L$16, financial_transactions35[[#This Row],[amount]]>$L$17), 1, 0) -> 1
A13: TXN_006854 | B13: 45297 | C13: CUST_3105 | D13: 1903.42 | E13: Legal | F13: South | G13: Direct Debit | H13: Tech Solutions Ltd | I13: =IF(OR(financial_transactions35[[#This Row],[amount]]<$L$16, financial_transactions35[[#This Row],[amount]]>$L$17), 1, 0) -> 1
A14: TXN_009200 | B14: 45328 | C14: CUST_6592 | D14: 1886.04 | E14: Office Supplies | F14: East | G14: Transfer | H14: Cloud Services Inc | I14: =IF(OR(financial_transactions35[[#This Row],[amount]]<$L$16, financial_transactions35[[#This Row],[amount]]>$L$17), 1, 0) -> 1
A15: TXN_005241 | B15: 45449 | C15: CUST_3657 | D15: 758.62 | E15: Office Supplies | F15: East | G15: Cash | H15: Maintenance Services | I15: =IF(OR(financial_transactions35[[#This Row],[amount]]<$L$16, financial_transactions35[[#This Row],[amount]]>$L$17), 1, 0) -> 1
A16: TXN_006394 | B16: 45633 | C16: CUST_7719 | D16: 926.7 | E16: It Services | F16: West | G16: Direct Debit | H16: Industrial Supply Co | I16: =IF(OR(financial_transactions35[[#This Row],[amount]]<$L$16, financial_transactions35[[#This Row],[amount]]>$L$17), 1, 0) -> 1
A17: TXN_004328 | B17: 45359 | C17: CUST_9975 | D17: 603.54 | E17: Travel | F17: North | G17: Card | H17: Unknown Merchant | I17: =IF(OR(financial_transactions35[[#This Row],[amount]]<$L$16, financial_transactions35[[#This Row],[amount]]>$L$17), 1, 0) -> 1
A18: TXN_005057 | B18: 45604 | C18: CUST_7691 | D18: 159.55 | E18: Marketing | F18: East | G18: Cash | H18: Advisory Partners | I18: =IF(OR(financial_transactions35[[#This Row],[amount]]<$L$16, financial_transactions35[[#This Row],[amount]]>$L$17), 1, 0) -> 1
A19: TXN_002009 | B19: 45360 | C19: CUST_2246 | D19: 1225.14 | E19: It Services | F19: East | G19: Cash | H19: Tech Solutions Ltd | I19: =IF(OR(financial_transactions35[[#This Row],[amount]]<$L$16, financial_transactions35[[#This Row],[amount]]>$L$17), 1, 0) -> 1
... A9218: TXN_004529 | B9218: 45535 | C9218: CUST_6919 | D9218: 672.05 | E9218: Equipment | F9218: South | G9218: Cash | H9218: Office Depot | I9218: =IF(OR(financial_transactions35[[#This Row],[amount]]<$L$16, financial_transactions35[[#This Row],[amount]]>$L$17), 1, 0) -> 1

Sheet Analysis
A1: DATA QUALITY SUMMARY
A2: Metric | B2: Value
A3: Original Row Count | B3: =COUNTA(Raw_Data!A:A)-1 -> 10000 | F3: Insert Chart: Transactions by Category (Pie Chart)
A4: Final Row Count | B4: =COUNTA('recommended work'!A:A)-1 -> 9217
A5: Rows Removed | B5: =B3-B4 -> 783
A6: % Data Retained | B6: =B4/B3 -> 0.9217
A7: Transactions Flagged | B7: =COUNTIF('recommended work'!I:I,1) -> 4608
A12: TRANSACTION SUMMARY
A13: Metric | B13: Value
A14: Date Range (Start) | B14: =MIN('recommended work'!B:B) -> 45292
A15: Date Range (End) | B15: =MAX('recommended work'!B:B) -> 45656
A16: Total Transaction Value | B16: =SUM('recommended work'!D:D) -> 15002116
A17: Average Transaction | B17: =AVERAGE('recommended work'!D:D) -> 1627.6572
A18: Median Transaction | B18: =MEDIAN('recommended work'!D:D) -> 1077.86 | F18: Insert Chart: Transactions by Region (Bar Chart)
F35: Insert Chart: Transactions Over Time (Line Chart)

Sheet Portfolio_Guide
A1: PORTFOLIO GUIDE
A3: WHAT YOU ACCOMPLISHED
A5: 1. Cleaned 10,000 financial transactions using Excel 2. Identified and resolved 5 data quality issues 3. Applied IQR method for outlier 4. Standardized categorical data for consistency 5. Created a summary dashboard for stakeholder reporting 6. Flagged high-value transactions (not deleted - showing business awareness)
A13: FOR YOUR PORTFOLIO FILES TO SAVE: 1. This completed workbook (.xlsx) 2. Screenshots of your dashboard (Analysis sheet) 3. (Optional) PDF export of key sheets
A19: HOW TO PRESENT THIS IN INTERVIEWS EXAMPLE TALKING POINT: "I completed a data cleaning project using Excel on 10,000 financial transactions. I identified missing values across 5 columns and applied appropriate handling strategies - deleting rows where critical fields like 'amount' were missing, but filling in categorical fields like 'merchant_name' with 'Unknown' for later investigation. I used the IQR method to detect outliers and added a flag column rather than automatically deleting high-value transactions, demonstrating understanding of financial data context. I also standardized categorical data using Find & Replace and the PROPER function to ensure consistency. Finally, I created a dashboard with summary metrics and visualisations to communicate data quality improvements to stakeholders. The project demonstrates my ability to deliver clean, analysis-ready datasets using Excel." | H19: KEY SKILLS DEMONSTRATED
H20: Data Inspection | J20: AutoFilter, Conditional Formatting
H21: Missing Value Handling | J21: Strategic deletion vs filling
H22: Outlier Detection | J22: IQR method with formulas
H23: Data Standardisation | J23: PROPER function, Find & Replace
H24: Formula Skills | J24: QUARTILE, IF, OR, COUNTIF
H25: Data Visualisation | J25: Charts and dashboard
H26: Business Awarenes | J26: Flagged outliers, didn't delete
H27: Documentation | J27: Clear summary metrics
A40: Keep this file! It's part of your growing data science portfolio.
D42: 🏆 CONGRATULATIONS! LAB 1B COMPLETE.

Sheet recommended work
A1: transaction_id | B1: date | C1: customer_id | D1: amount | E1: Category | F1: region | G1: payment_method | H1: merchant_name | I1: outlier_flag
A2: TXN_001114 | B2: 45352 | C2: CUST_3711 | D2: 863.13 | E2: Training | F2: West | G2: Cash | H2: Marketing Agency Ltd | I2: =IF(OR(financial_transactions3[[#This Row],[amount]]<$L$16, financial_transactions3[[#This Row],[amount]]>$L$17), 1, 0) -> 0 | J2: Missing Data
A3: TXN_006267 | B3: 45444 | C3: CUST_6073 | D3: 1783.51 | E3: Marketing | F3: South | G3: Transfer | H3: Advisory Partners | I3: =IF(OR(financial_transactions3[[#This Row],[amount]]<$L$16, financial_transactions3[[#This Row],[amount]]>$L$17), 1, 0) -> 1 | J3: transaction_id | K3: =COUNTBLANK(A2:A9218) -> 0
A4: TXN_005820 | B4: 45566 | C4: CUST_2381 | D4: 1200.51 | E4: Travel | F4: North | G4: Transfer | H4: Tech Solutions Ltd | I4: =IF(OR(financial_transactions3[[#This Row],[amount]]<$L$16, financial_transactions3[[#This Row],[amount]]>$L$17), 1, 0) -> 0 | J4: =financial_transactions3[[#Headers],[date]] -> date | K4: =COUNTBLANK(B2:B9218) -> 0
A5: TXN_004797 | B5: 45384 | C5: CUST_4899 | D5: 1981.6 | E5: Travel | F5: South | G5: Cash | H5: Cloud Services Inc | I5: =IF(OR(financial_transactions3[[#This Row],[amount]]<$L$16, financial_transactions3[[#This Row],[amount]]>$L$17), 1, 0) -> 1 | J5: =financial_transactions3[[#Headers],[customer_id]] -> customer_id | K5: =COUNTBLANK(C2:C9218) -> 0
A6: TXN_004823 | B6: 45414 | C6: CUST_2342 | D6: 943.9 | E6: Marketing | F6: South | G6: Direct Debit | H6: Conference Center | I6: =IF(OR(financial_transactions3[[#This Row],[amount]]<$L$16, financial_transactions3[[#This Row],[amount]]>$L$17), 1, 0) -> 0 | J6: =financial_transactions3[[#Headers],[amount]] -> amount | K6: =COUNTBLANK(D2:D9218) -> 0
A7: TXN_009190 | B7: 45354 | C7: CUST_1255 | D7: 1147.27 | E7: Uncategorised | F7: North | G7: Cash | H7: Stationary World | I7: =IF(OR(financial_transactions3[[#This Row],[amount]]<$L$16, financial_transactions3[[#This Row],[amount]]>$L$17), 1, 0) -> 0 | J7: =financial_transactions3[[#Headers],[Category]] -> Category | K7: =COUNTBLANK(D2:D9218) -> 0
A8: TXN_009475 | B8: 45476 | C8: CUST_7457 | D8: 1772.48 | E8: Maintenance | F8: North | G8: Card | H8: Legal Advisors | I8: =IF(OR(financial_transactions3[[#This Row],[amount]]<$L$16, financial_transactions3[[#This Row],[amount]]>$L$17), 1, 0) -> 1 | J8: =financial_transactions3[[#Headers],[region]] -> region | K8: =COUNTBLANK(F1:F9218) -> 0
A9: TXN_001489 | B9: 45507 | C9: CUST_1894 | D9: 108.64 | E9: Equipment | F9: North | G9: Direct Debit | H9: Software Vendor | I9: =IF(OR(financial_transactions3[[#This Row],[amount]]<$L$16, financial_transactions3[[#This Row],[amount]]>$L$17), 1, 0) -> 1 | J9: =financial_transactions3[[#Headers],[payment_method]] -> payment_method | K9: =COUNTBLANK(G1:G9218) -> 0
A10: TXN_000008 | B10: 45538 | C10: CUST_5426 | D10: 277.27 | E10: It Services | F10: West | G10: Direct Debit | H10: Maintenance Services | I10: =IF(OR(financial_transactions3[[#This Row],[amount]]<$L$16, financial_transactions3[[#This Row],[amount]]>$L$17), 1, 0) -> 1 | J10: =financial_transactions3[[#Headers],[merchant_name]] -> merchant_name | K10: =COUNTBLANK(H1:H9218) -> 0
A11: TXN_003162 | B11: 45599 | C11: CUST_7614 | D11: 5217.33 | E11: It Services | F11: East | G11: Cash | H11: Cloud Services Inc | I11: =IF(OR(financial_transactions3[[#This Row],[amount]]<$L$16, financial_transactions3[[#This Row],[amount]]>$L$17), 1, 0) -> 1
A12: TXN_003740 | B12: 45447 | C12: CUST_1919 | D12: 1155.72 | E12: Utilities | F12: North | G12: Transfer | H12: Marketing Agency Ltd | I12: =IF(OR(financial_transactions3[[#This Row],[amount]]<$L$16, financial_transactions3[[#This Row],[amount]]>$L$17), 1, 0) -> 0
A13: TXN_006854 | B13: 45297 | C13: CUST_3105 | D13: 1903.42 | E13: Legal | F13: South | G13: Direct Debit | H13: Tech Solutions Ltd | I13: =IF(OR(financial_transactions3[[#This Row],[amount]]<$L$16, financial_transactions3[[#This Row],[amount]]>$L$17), 1, 0) -> 1
A14: TXN_009200 | B14: 45328 | C14: CUST_6592 | D14: 1886.04 | E14: Office Supplies | F14: East | G14: Transfer | H14: Cloud Services Inc | I14: =IF(OR(financial_transactions3[[#This Row],[amount]]<$L$16, financial_transactions3[[#This Row],[amount]]>$L$17), 1, 0) -> 1 | K14: Formula
A15: TXN_005241 | B15: 45449 | C15: CUST_3657 | D15: 758.62 | E15: Office Supplies | F15: East | G15: Cash | H15: Maintenance Services | I15: =IF(OR(financial_transactions3[[#This Row],[amount]]<$L$16, financial_transactions3[[#This Row],[amount]]>$L$17), 1, 0) -> 0 | K15: Metric | L15: Formula
A16: TXN_006394 | B16: 45633 | C16: CUST_7719 | D16: 926.7 | E16: It Services | F16: West | G16: Direct Debit | H16: Industrial Supply Co | I16: =IF(OR(financial_transactions3[[#This Row],[amount]]<$L$16, financial_transactions3[[#This Row],[amount]]>$L$17), 1, 0) -> 0 | K16: Q1 | L16: =_xlfn.QUARTILE.INC(D:D,1) -> 570.95
A17: TXN_004328 | B17: 45359 | C17: CUST_9975 | D17: 603.54 | E17: Travel | F17: North | G17: Card | H17: Unknown Merchant | I17: =IF(OR(financial_transactions3[[#This Row],[amount]]<$L$16, financial_transactions3[[#This Row],[amount]]>$L$17), 1, 0) -> 0 | K17: Q3 | L17: =_xlfn.QUARTILE.INC(D:D,3) -> 1598.07
A18: TXN_005057 | B18: 45604 | C18: CUST_7691 | D18: 159.55 | E18: Marketing | F18: East | G18: Cash | H18: Advisory Partners | I18: =IF(OR(financial_transactions3[[#This Row],[amount]]<$L$16, financial_transactions3[[#This Row],[amount]]>$L$17), 1, 0) -> 1 | K18: IQR | L18: =L17-L16 -> 1027.12
A19: TXN_002009 | B19: 45360 | C19: CUST_2246 | D19: 1225.14 | E19: It Services | F19: East | G19: Cash | H19: Tech Solutions Ltd | I19: =IF(OR(financial_transactions3[[#This Row],[amount]]<$L$16, financial_transactions3[[#This Row],[amount]]>$L$17), 1, 0) -> 0 | K19: Lower Bound | L19: =L16-1.5*L18 -> -969.73
A20: TXN_008775 | B20: 45360 | C20: CUST_2912 | D20: 1899.33 | E20: Equipment | F20: North | G20: Direct Debit | H20: Unknown Merchant | I20: =IF(OR(financial_transactions3[[#This Row],[amount]]<$L$16, financial_transactions3[[#This Row],[amount]]>$L$17), 1, 0) -> 1 | K20: Upper Bound | L20: =L17+1.5*L18 -> 3138.75
A21: TXN_004566 | B21: 45635 | C21: CUST_5042 | D21: 931.16 | E21: Utilities | F21: North | G21: Card | H21: Cloud Services Inc | I21: =IF(OR(financial_transactions3[[#This Row],[amount]]<$L$16, financial_transactions3[[#This Row],[amount]]>$L$17), 1, 0) -> 0
A22: TXN_005371 | B22: 45635 | C22: CUST_4201 | D22: 110.46 | E22: Uncategorised | F22: East | G22: Card | H22: Maintenance Services | I22: =IF(OR(financial_transactions3[[#This Row],[amount]]<$L$16, financial_transactions3[[#This Row],[amount]]>$L$17), 1, 0) -> 1
A23: TXN_003483 | B23: 45361 | C23: CUST_1644 | D23: 412.95 | E23: Utilities | F23: South | G23: Cash | H23: Learning Academy | I23: =IF(OR(financial_transactions3[[#This Row],[amount]]<$L$16, financial_transactions3[[#This Row],[amount]]>$L$17), 1, 0) -> 1
A24: TXN_004348 | B24: 45422 | C24: CUST_2902 | D24: 1161.23 | E24: Training | F24: East | G24: Cash | H24: Unknown Merchant | I24: =IF(OR(financial_transactions3[[#This Row],[amount]]<$L$16, financial_transactions3[[#This Row],[amount]]>$L$17), 1, 0) -> 0
A25: TXN_001881 | B25: 45545 | C25: CUST_8967 | D25: 1900.35 | E25: It Services | F25: North | G25: Card | H25: Tech Solutions Ltd | I25: =IF(OR(financial_transactions3[[#This Row],[amount]]<$L$16, financial_transactions3[[#This Row],[amount]]>$L$17), 1, 0) -> 1
A26: TXN_006677 | B26: 45545 | C26: CUST_6972 | D26: 936.79 | E26: Equipment | F26: North | G26: Direct Debit | H26: Learning Academy | I26: =IF(OR(financial_transactions3[[#This Row],[amount]]<$L$16, financial_transactions3[[#This Row],[amount]]>$L$17), 1, 0) -> 0
A27: TXN_007073 | B27: 45606 | C27: CUST_1393 | D27: 299.37 | E27: Office Supplies | F27: East | G27: Direct Debit | H27: Stationary World | I27: =IF(OR(financial_transactions3[[#This Row],[amount]]<$L$16, financial_transactions3[[#This Row],[amount]]>$L$17), 1, 0) -> 1
A28: TXN_000437 | B28: 45636 | C28: CUST_1412 | D28: 1019.84 | E28: Maintenance | F28: West | G28: Cash | H28: Learning Academy | I28: =IF(OR(financial_transactions3[[#This Row],[amount]]<$L$16, financial_transactions3[[#This Row],[amount]]>$L$17), 1, 0) -> 0
A29: TXN_008588 | B29: 45576 | C29: CUST_2883 | D29: 1768.53 | E29: Training | F29: East | G29: Card | H29: Industrial Supply Co | I29: =IF(OR(financial_transactions3[[#This Row],[amount]]<$L$16, financial_transactions3[[#This Row],[amount]]>$L$17), 1, 0) -> 1
A30: TXN_006791 | B30: 45607 | C30: CUST_7571 | D30: 1601.95 | E30: Travel | F30: North | G30: Cash | H30: City Hotel | I30: =IF(OR(financial_transactions3[[#This Row],[amount]]<$L$16, financial_transactions3[[#This Row],[amount]]>$L$17), 1, 0) -> 1
A31: TXN_009741 | B31: 45455 | C31: CUST_6606 | D31: 662.11 | E31: Training | F31: South | G31: Cash | H31: Tech Solutions Ltd | I31: =IF(OR(financial_transactions3[[#This Row],[amount]]<$L$16, financial_transactions3[[#This Row],[amount]]>$L$17), 1, 0) -> 0
A32: TXN_008610 | B32: 45547 | C32: CUST_4883 | D32: 1460.32 | E32: Legal | F32: North | G32: Card | H32: Software Vendor | I32: =IF(OR(financial_transactions3[[#This Row],[amount]]<$L$16, financial_transactions3[[#This Row],[amount]]>$L$17), 1, 0) -> 0
... A9218: TXN_004529 | B9218: 45535 | C9218: CUST_6919 | D9218: 672.05 | E9218: Equipment | F9218: South | G9218: Cash | H9218: Office Depot | I9218: =IF(OR(financial_transactions3[[#This Row],[amount]]<$L$16, financial_transactions3[[#This Row],[amount]]>$L$17), 1, 0) -> 0

Sheet Pivote tables
A3: Row Labels | B3: Count of transaction_id
A4: East | B4: 2205
A5: North | B5: 2512
A6: South | B6: 2277
A7: West | B7: 2223
A8: (blank)
A9: Grand Total | B9: 9217
A12: Row Labels | B12: Count of transaction_id
A13: Consulting | B13: 862
A14: Equipment | B14: 831
A15: It Services | B15: 852
A16: Legal | B16: 872
A17: Maintenance | B17: 828
A18: Marketing | B18: 859
A19: Office Supplies | B19: 825
A20: Training | B20: 875
A21: Travel | B21: 834
A22: Uncategorised | B22: 743
A23: Utilities | B23: 836
A24: (blank)
A25: Grand Total | B25: 9217
A27: Row Labels | B27: Count of transaction_id
A28: <01/01/2024
A29: Jan | B29: 795
A30: Feb | B30: 719
A31: Mar | B31: 832
A32: Apr | B32: 729
A33: May | B33: 767
A34: Jun | B34: 740
A35: Jul | B35: 781
A36: Aug | B36: 783
A37: Sep | B37: 759
A38: Oct | B38: 800
A39: Nov | B39: 763
A40: Dec | B40: 749
A41: Grand Total | B41: 9217
